Workbook

Sheet 1
D1: PENAWARAN REKANAN
D2: (REKAPITULASI BIAYA PROYEK)
D3: PROYEK | E3: : | F3: JASA PEKERJAAN PEMERIKSAAN BAWAH AIR STRUKTUR PILE AREA LOADING DOCK 2 DAN COOLING WATER INTAKE
D4: NO.KONTRAK | E4: : | F4: CA-25021
D5: SISTEM KONTRAK | E5: : | F5: LUMPSUM
D6: SCHEDULE | E6: : | F6: 9
I7: FORM - 1
A8: No. | B8: URAIAN | H8: TOTAL (Rp) | I8: KETERANGAN | N8: KDN | O8: KLN | P8: TOTAL BIAYA | Q8: %TKDN
B9: BIAYA LUMPSUM
A10: 1 | B10: BIAYA JASA | H10: ='4'!H39 -> 2103545000 | I10: / Kontrak | N10: ='4'!S39 -> 2103545000 | O10: ='4'!T39 -> 0 | P10: =N10+O10 -> 2103545000 | Q10: =N10/$P$18 -> 0.65818157
A11: 2 | B11: BIAYA PERALATAN | H11: ='4'!H59 -> 669500000 | I11: / Kontrak | N11: ='4'!S59 -> 502125000 | O11: ='4'!T59 -> 167375000 | P11: =N11+O11 -> 669500000 | Q11: =N11/$P$18 -> 0.1571107
A12: 3 | B12: BIAYA MATERIAL | H12: ='4'!H75 -> 399950000 | I12: / Kontrak | N12: ='4'!S75 -> 22500000 | O12: ='4'!T75 -> 399950000 | P12: =N12+O12 -> 422450000 | Q12: =N12/$P$18 -> 0.0070400611
A13: 4 | B13: SUB TOTAL I | H13: =SUM(H10:H12) -> 3172995000 | I13: / Kontrak
A14: 5 | B14: OVERHEAD = ( …%) x (Sub Total) | E14: DARI FORM 07 | H14: ='7'!L24 -> 500000 | I14: / Kontrak | N14: ='7'!R24 -> 500000 | O14: ='7'!S24 -> 0 | P14: =N14+O14 -> 500000 | Q14: =N14/$P$18 -> 0.0001564458
A15: 6 | B15: PROFIT = ( …%) x (Sub Total + Overhead) | G15: 0.08 | H15: =(H13+H14)*G15 -> 253879600 | I15: / Kontrak
A16: 7 | B16: SUB TOTAL I | H16: =SUM(H13:H15) -> 3427374600 | I16: / Kontrak
A17: 8 | B17: CGL | H17: 10000000 | I17: / Kontrak | N17: ='7'!R27 -> 0 | O17: ='7'!S27 -> 0 | P17: =N17+O17 -> 0 | Q17: =N17/$P$18 -> 0
A18: 9 | B18: TOTAL HARGA LUMPSUM | H18: =H16+H17 -> 3437374600 | I18: / Kontrak | N18: =SUM(N10:N15) -> 2628670000 | O18: =SUM(O10:O15) -> 567325000 | P18: =SUM(P10:P15) -> 3195995000 | Q18: =N18/P18 -> 0.82248877
A19: 10 | B19: PEMBULATAN | H19: =ROUND(H18,-3) -> 3437375000 | I19: =I10 -> / Kontrak | N19: KOMPONEN NON BIAYA (PROFIT) | P19: =H15 -> 253879600
N20: TOTAL NILAI PENAWARAN | P20: =SUM(P18:P19) -> 3449874600
B21: CATATAN :
A22: 1 | B22: Formulir ini digunakan hanya sebagai panduan didalam perhitungan penawaran dan bahan evaluasi penawaran, adapun jika terdapat kekurangan dan kelebihan, maka rekanan dapat menyempurnakan sesuai dengan penjelasan lingkup kerja dan dokumen pengadaan dan segala bentuk kesalahan dalam penawaran menjadi tanggung jawab rekanan.
A23: 2 | B23: Untuk lebih mempermudah rekanan dalam melakukan perhitungan, disarankan agar perhitungan dimulai dari Form-04, Form-07, lalu Form-01, serta membaca keterkaitan perhitungan dari setiap Form. Rekanan diperbolehkan melakukan penyesuaian terhadap form ini bila dianggap jumlah baris yang disediakan belum dapat memenuhi kebutuhan rekanan.
A24: 3 | B24: Rekanan diharapkan untuk meneliti ulang setiap perhitungan dan hubungan antar perhitungan disetiap formulir.
A25: 4 | B25: CGL dengan nilai pertanggungan USD 1,000,000,00
A26: 5 | B26: Nilai penawaran diharapkan mempertimbangkan PPh namun belum termasuk PPN.

Sheet 4
C1: ='1'!$D$1 -> PENAWARAN REKANAN
C2: (ANALISA BIAYA UNIT PEKERJAAN)
C3: PROYEK | D3: : | E3: ='1'!F3 -> JASA PEKERJAAN PEMERIKSAAN BAWAH AIR STRUKTUR PILE AREA LOADING DOCK 2 DAN COOLING WATER INTAKE
C4: NO. KONTRAK | D4: : | E4: ='1'!F4 -> CA-25021
C5: SISTEM KONTRAK | D5: : | E5: ='1'!F5 -> LUMPSUM
C6: SCHEDULE | D6: : | E6: ='1'!F6 -> 9
I7: FORM - 4
A8: I. | B8: PEKERJAAN LUMPSUM (L/S)
A10: 1. | B10: BIAYA TENAGA KERJA
A11: NO. | B11: KOMPOSISI CREW | D11: JUMLAH TENAGA KERJA | F11: DURASI | G11: UPAH ALL IN (Rp) | H11: TOTAL UPAH | I11: KETERANGAN | S11: Komponen Dalam Negeri (KDN) | T11: Komponen Luar Negeri (KLN)
B13: Petunjuk perkalian ððð | D13: [1] | F13: [2] | G13: [3] | H13: [4]= [1] x [2] x [3]
A14: 1 | B14: Ahli Struktur | D14: 1 | F14: 8 | G14: 20000000 | H14: =D14*F14*G14 -> 160000000 | I14: / KONTRAK | S14: =H14 -> 160000000
A15: 2 | B15: Ahli Material | D15: 1 | F15: 8 | G15: 20000000 | H15: =D15*F15*G15 -> 160000000 | I15: / KONTRAK | S15: =H15 -> 160000000
A16: 3 | B16: Diving Supervisor | D16: 1 | F16: 7 | G16: 63815000 | H16: =D16*F16*G16 -> 446705000 | I16: / KONTRAK | S16: =H16 -> 446705000
A17: 4 | B17: Lead Diver | D17: 1 | F17: 7 | G17: 44400000 | H17: =D17*F17*G17 -> 310800000 | I17: / KONTRAK | S17: =H17 -> 310800000
A18: 5 | B18: Diver NDT Level II | D18: 2 | F18: 7 | G18: 45800000 | H18: =D18*F18*G18 -> 641200000 | I18: / KONTRAK | S18: =H18 -> 641200000
A19: 6 | B19: Diver | D19: 2 | F19: 7 | G19: 20810000 | H19: =D19*F19*G19 -> 291340000 | I19: / KONTRAK | S19: =H19 -> 291340000
A20: 7 | B20: Diver Technician | D20: 1 | F20: 7 | G20: 6000000 | H20: =D20*F20*G20 -> 42000000 | I20: =I18 -> / KONTRAK | S20: =H20 -> 42000000
C22: Total Orang = | D22: =SUM(D14:D20) -> 9 | G22: Sub Total-1 = | H22: =SUBTOTAL(9,H14:H20) -> 2052045000 | I22: =I14 -> / KONTRAK | S22: =SUM(S14:S21) -> 2052045000 | T22: =SUM(T14:T21) -> 0
A24: 2 | B24: MOBILISASI DAN DEMOBILISASI CONSTRUCTION PHASE
A25: NO. | B25: URAIAN BIAYA | D25: QTY | F25: FREQ | G25: HARGA SATUAN | H25: TOTAL UPAH | I25: KETERANGAN
B27: Petunjuk perkalian ððð | D27: [1] | F27: [2] | G27: [3] | H27: [4]= [1] x [2] x [3]
A29: 1 | B29: Mob Demob Personil | D29: 9 | F29: 1 | G29: 3500000 | H29: =D29*F29*G29 -> 31500000 | I29: /KONTRAK | S29: =H29 -> 31500000
A30: 2 | B30: Equipment Handling | D30: 1 | F30: 1 | G30: 20000000 | H30: =D30*F30*G30 -> 20000000 | I30: /KONTRAK | S30: =H30 -> 20000000
A31: 3 | H31: =D31*F31*G31 -> 0 | I31: /KONTRAK | S31: =H31 -> 0
A32: 4 | H32: =D32*F32*G32 -> 0 | I32: =I31 -> /KONTRAK | S32: =H32 -> 0
A33: 5 | H33: =D33*F33*G33 -> 0 | I33: =I31 -> /KONTRAK | S33: =H33 -> 0
G38: Sub Total-2 = | H38: =SUBTOTAL(9,H29:H36) -> 51500000 | I38: =I30 -> /KONTRAK | S38: =SUM(S29:S37) -> 51500000 | T38: =SUM(T29:T37) -> 0
B39: SUB TOTAL BIAYA JASA | H39: =SUBTOTAL(9,H14:H38) -> 2103545000 | I39: =I29 -> /KONTRAK | S39: =S22+S38 -> 2103545000 | T39: =T22+T38 -> 0
A41: 3 | B41: BIAYA PERALATAN
A42: NO. | B42: URAIAN BIAYA | D42: QTY | F42: FREQ | G42: HARGA SATUAN | H42: TOTAL BIAYA | I42: KETERANGAN
B44: Petunjuk perkalian ððð | D44: [1] | F44: [2] | G44: [3] | H44: [4]= [1] x [2] x [3]
A45: 1 | B45: Kendaraan diesel dengan ATPL | D45: 1 | F45: 1 | G45: 95000000 | H45: =D45*G45*F45 -> 95000000 | I45: /KONTRAK | S45: =0.75*H45 -> 71250000 | T45: =0.25*H45 -> 23750000
A46: 2 | B46: APD | D46: 9 | F46: 1 | G46: 2800000 | H46: =D46*G46*F46 -> 25200000 | I46: /KONTRAK | S46: =0.75*H46 -> 18900000 | T46: =0.25*H46 -> 6300000
A47: 3 | B47: Surface cleaning tools | D47: 1 | F47: 5 | G47: 7200000 | H47: =D47*G47*F47 -> 36000000 | I47: /KONTRAK | S47: =0.75*H47 -> 27000000 | T47: =0.25*H47 -> 9000000
A48: 4 | B48: Ultrasonic thickness | D48: 1 | F48: 5 | G48: 12500000 | H48: =D48*G48*F48 -> 62500000 | I48: /KONTRAK | S48: =0.75*H48 -> 46875000 | T48: =0.25*H48 -> 15625000
A49: 5 | B49: Rebound hammer | D49: 1 | F49: 5 | G49: 1440000 | H49: =D49*G49*F49 -> 7200000 | I49: /KONTRAK | S49: =0.75*H49 -> 5400000 | T49: =0.25*H49 -> 1800000
A50: 6 | B50: Alat untuk mengukur potensial proteksi katodik | D50: 1 | F50: 5 | G50: 12500000 | H50: =D50*G50*F50 -> 62500000 | I50: /KONTRAK | S50: =0.75*H50 -> 46875000 | T50: =0.25*H50 -> 15625000
A51: 7 | B51: Peralatan pendukung pemeriksaan | D51: 1 | F51: 5 | G51: 720000 | H51: =D51*G51*F51 -> 3600000 | I51: /KONTRAK | S51: =0.75*H51 -> 2700000 | T51: =0.25*H51 -> 900000
A52: 8 | B52: Kamera digital underwater | D52: 2 | F52: 5 | G52: 1500000 | H52: =D52*G52*F52 -> 15000000 | I52: /KONTRAK | S52: =0.75*H52 -> 11250000 | T52: =0.25*H52 -> 3750000
...

Sheet 7
H1: ='1'!D1 -> PENAWARAN REKANAN
H2: (ANALISA BIAYA OVERHEAD)
H3: PROYEK | J3: : | K3: ='1'!F3 -> JASA PEKERJAAN PEMERIKSAAN BAWAH AIR STRUKTUR PILE AREA LOADING DOCK 2 DAN COOLING WATER INTAKE
H4: NO. KONTRAK | J4: : | K4: ='1'!F4 -> CA-25021
H5: SISTEM KONTRAK | J5: : | K5: ='1'!F5 -> LUMPSUM
H6: SCHEDULE | J6: : | K6: ='1'!F6 -> 9
M7: FORM - 7
A9: NO. | B9: URAIAN | I9: QTY | J9: UNIT | K9: HARGA SATUAN | L9: TOTAL | M9: KETERANGAN | R9: KDN | S9: KLN
K10: (Rp) | L10: (Rp)
A11: A | B11: BIAYA LANGSUNG
A12: 1 | B12: BIAYA JASA | L12: ='1'!H10 -> 2103545000 | M12: /Kontrak
A13: 2 | B13: BIAYA ALAT | L13: ='1'!H11 -> 669500000 | M13: /Kontrak
A14: 2 | B14: BIAYA MATERIAL | L14: ='1'!H12 -> 399950000 | M14: /Kontrak
K15: Sub Total-A | L15: =SUM(L12:L14) -> 3172995000 | M15: /Kontrak
A16: B | B16: BIAYA TIDAK LANGSUNG (OVERHEAD)
B17: Biaya Perumahan | I17: 0.25 | J17: 1 | K17: 2000000 | L17: =I17*K17 -> 500000 | M17: /Bulan | R17: =L17 -> 500000
R18: =L18 -> 0
R19: =L19 -> 0
B22: Biaya Tidak LangsungTotal-B = | L22: =SUM(L17:L21) -> 500000 | M22: /Kontrak
A24: C | B24: Total Biaya Tidak Langsung selama Kontrak ðð Total-B X 18 Bulan | L24: =L22 -> 500000 | M24: =M15 -> /Kontrak | R24: =SUM(R17:R23) -> 500000 | S24: =SUM(S17:S23) -> 0
L25: isikan ke FORM-2 kolom OVERHEAD

Sheet buffer
A1: Statistics Summary
A2: Minimum | B2: 6.7705064e+08 | C2: 0.05 | D2: 9.0298121e+08 | F2: CA-25021 JP PEMERIKSAAN BAWAH AIR STRUKTUR PILE LOADING DOCK 2 DAN COOLING WATER | G2: 6.7705064e+08 | H2: 30 | I2: 0.0015544041 | L2: 1 | M2: 1 | N2: 0.052388854 | O2: 2 | P2: 6.7705064e+08 | Q2: 30 | T2: 0.0015544041
A3: Maximum | B3: 1.8447184e+09 | C3: 0.1 | D3: 9.8660375e+08 | F3: 19300 | G3: 6.9558505e+08 | H3: 45 | I3: 0.0038860104 | L3: 2 | M3: 2 | N3: 0.054915016 | O3: 65 | P3: 6.9558505e+08 | Q3: 45 | T3: 0.0038860104
A4: Mean | B4: 1.2643655e+09 | C4: 0.15 | D4: 1.046093e+09 | F4: 31 | G4: 7.1411945e+08 | H4: 0 | I4: 0.0038860104 | L4: 3 | M4: 3 | N4: 0.066423933 | P4: 7.1411945e+08 | Q4: 0 | T4: 0.0038860104
A5: Std Dev | B5: 2.2464782e+08 | C5: 0.2 | D5: 1.0887657e+09 | F5: 1 | G5: 7.3265386e+08 | H5: 76 | I5: 0.0078238342 | L5: 4 | M5: 4 | N5: 0.065394119 | P5: 7.3265386e+08 | Q5: 76 | T5: 0.0078238342
A6: Variance | B6: 5.0466644e+16 | C6: 0.25 | D6: 1.1234332e+09 | F6: Monte Carlo | G6: 7.5118827e+08 | H6: 24 | I6: 0.0090673575 | L6: 5 | M6: 5 | N6: 0.0040973999 | P6: 7.5118827e+08 | Q6: 24 | T6: 0.0090673575
A7: Skewness | B7: -0.057328612 | C7: 0.3 | D7: 1.155519e+09 | F7: 45834.357 | G7: 7.6972268e+08 | H7: 22 | I7: 0.010207254 | L7: 6 | M7: 6 | N7: 0.079950699 | P7: 7.6972268e+08 | Q7: 22 | T7: 0.010207254
A8: Kurtosis | B8: -0.18782681 | C8: 0.35 | D8: 1.1820177e+09 | F8: 0,16211 seconds | G8: 7.8825709e+08 | H8: 75 | I8: 0.014093264 | L8: 7 | M8: 7 | N8: 0.0042254436 | P8: 7.8825709e+08 | Q8: 75 | T8: 0.014093264
A9: Median | B9: 1.2629459e+09 | C9: 0.4 | D9: 1.2084762e+09 | F9: 45834.357 | G9: 8.067915e+08 | H9: 102 | I9: 0.019378238 | L9: 8 | M9: 8 | N9: 0.025897987 | P9: 8.067915e+08 | Q9: 102 | T9: 0.019378238
A10: Mode | B10: 1.2069842e+09 | C10: 0.45 | D10: 1.2351217e+09 | G10: 8.2532591e+08 | H10: 96 | I10: 0.024352332 | J10: 713 | L10: 9 | M10: 9 | N10: 0.019085656 | P10: 8.2532591e+08 | Q10: 96 | T10: 0.024352332
A11: Left X | B11: 8.0963996e+08 | C11: 0.5 | D11: 1.2629459e+09 | G11: 8.4386031e+08 | H11: 99 | I11: 0.029481865 | L11: 10 | M11: 10 | N11: 0.00088487579 | P11: 8.4386031e+08 | Q11: 99 | T11: 0.029481865
A12: Left P | B12: 2,00% | C12: 0.55 | D12: 1.2916345e+09 | G12: 8.6239472e+08 | H12: 98 | I12: 0.034559585 | L12: 11 | M12: 11 | N12: 0.0024862863 | P12: 8.6239472e+08 | Q12: 98 | T12: 0.034559585
A13: Right X | B13: 1703018000 | C13: 0.6 | D13: 1.3202513e+09 | G13: 8.8092913e+08 | H13: 151 | I13: 0.04238342 | L13: 12 | M13: 12 | N13: 0.011356317 | P13: 8.8092913e+08 | Q13: 151 | T13: 0.04238342
A14: Right P | B14: 98,00% | C14: 0.65 | D14: 1.3498775e+09 | G14: 8.9946354e+08 | H14: 144 | I14: 0.04984456 | L14: 13 | M14: 13 | N14: 0.017041774 | P14: 8.9946354e+08 | Q14: 144 | T14: 0.04984456
A15: Diff X | B15: 8.9337804e+08 | C15: 0.7 | D15: 1.3821173e+09 | G15: 9.1799795e+08 | H15: 174 | I15: 0.058860104 | L15: 14 | M15: 14 | N15: 0.015497023 | P15: 9.1799795e+08 | Q15: 174 | R15: 713 | T15: 0.058860104
A16: Diff P | B16: 96,00% | C16: 0.75 | D16: 1.4138061e+09 | G16: 9.3653236e+08 | H16: 174 | I16: 0.067875648 | L16: 15 | M16: 15 | N16: 0.018435813 | P16: 9.3653236e+08 | Q16: 174 | T16: 0.067875648
A17: Upper | B17: 98 | C17: 0.8 | D17: 1.4491488e+09 | G17: 9.5506676e+08 | H17: 202 | I17: 0.078341969 | L17: 16 | M17: 16 | N17: 0.017580699 | P17: 9.5506676e+08 | Q17: 202 | T17: 0.078341969
A18: Lower | B18: 2 | C18: 0.85 | D18: 1.4874512e+09 | G18: 9.7360117e+08 | H18: 217 | I18: 0.089585492 | L18: 17 | M18: 17 | N18: 0.0017580699 | P18: 9.7360117e+08 | Q18: 217 | T18: 0.089585492
A19: MinLoc | B19: $H$25 | C19: 0.9 | D19: 1.5376217e+09 | G19: 9.9213558e+08 | H19: 272 | I19: 0.10367876 | L19: 18 | M19: 18 | N19: 0.019890291 | P19: 9.9213558e+08 | Q19: 272 | T19: 0.10367876
A20: MostLoc | B20: $H$26 | C20: 0.95 | D20: 1.6139431e+09 | G20: 1.01067e+09 | H20: 302 | I20: 0.11932642 | L20: 19 | M20: 19 | N20: 3.5161399e-09 | P20: 1.01067e+09 | Q20: 302 | T20: 0.11932642
A21: MaxLoc | B21: $H$27 | G21: 1.0292044e+09 | H21: 293 | I21: 0.13450777 | L21: 20 | M21: 20 | N21: 1.7580699e-08 | P21: 1.0292044e+09 | Q21: 293 | T21: 0.13450777
A22: SheetName | B22: HPS | G22: 1.0477388e+09 | H22: 349 | I22: 0.15259067 | L22: 21 | M22: 21 | N22: 0.035161399 | P22: 1.0477388e+09 | Q22: 349 | T22: 0.15259067
G23: 1.0662732e+09 | H23: 375 | I23: 0.17202073 | L23: 22 | M23: 22 | N23: 0.0035161399 | P23: 1.0662732e+09 | Q23: 375 | T23: 0.17202073
G24: 1.0848076e+09 | H24: 459 | I24: 0.19580311 | L24: 23 | M24: 19 | N24: 3.5161399e-09 | P24: 1.0848076e+09 | Q24: 459 | T24: 0.19580311
G25: 1.103342e+09 | H25: 483 | I25: 0.22082902 | L25: 24 | M25: 24 | N25: 0.0034150631 | P25: 1.103342e+09 | Q25: 483 | T25: 0.22082902
G26: 1.1218764e+09 | H26: 534 | I26: 0.24849741 | L26: 25 | M26: 25 | N26: 7.0322797e-12 | P26: 1.1218764e+09 | Q26: 534 | T26: 0.24849741
G27: 1.1404108e+09 | H27: 537 | I27: 0.27632124 | L27: 26 | M27: 26 | N27: 0.0021194285 | P27: 1.1404108e+09 | Q27: 537 | T27: 0.27632124
G28: 1.1589453e+09 | H28: 607 | I28: 0.30777202 | L28: 27 | M28: 27 | N28: 1.7580699e-10 | P28: 1.1589453e+09 | Q28: 607 | T28: 0.30777202
G29: 1.1774797e+09 | H29: 641 | I29: 0.34098446 | L29: 28 | M29: 22 | N29: 0.0035161399 | P29: 1.1774797e+09 | Q29: 641 | T29: 0.34098446
G30: 1.1960141e+09 | H30: 654 | I30: 0.37487047 | L30: 29 | M30: 29 | N30: 0.0020300443 | P30: 1.1960141e+09 | Q30: 654 | T30: 0.37487047
G31: 1.2145485e+09 | H31: 684 | I31: 0.41031088 | L31: 30 | M31: 30 | N31: 0.00053709924 | P31: 1.2145485e+09 | Q31: 684 | T31: 0.41031088
G32: 1.2330829e+09 | H32: 713 | I32: 0.44725389 | L32: 31 | M32: 31 | N32: 0.47239441 | P32: 1.2330829e+09 | Q32: 713 | T32: 0.44725389
G33: 1.2516173e+09 | H33: 643 | I33: 0.48056995 | L33: 32 | M33: 32 | N33: 0.056119295 | P33: 1.2516173e+09 | Q33: 643 | T33: 0.48056995
G34: 1.2701517e+09 | H34: 641 | I34: 0.51378238 | L34: 33 | M34: 33 | N34: 0.00202691 | P34: 1.2701517e+09 | Q34: 641 | T34: 0.51378238
... G52: 1.6037711e+09 | H52: 198 | I52: 0.94507772 | L52: 51 | M52: 51 | N52: 9.489394e-05 | P52: 1.6037711e+09 | Q52: 198 | T52: 0.94507772
G53: 1.6223055e+09 | H53: 174 | I53: 0.95409326 | L53: 52 | M53: 52 | N53: 2.3723485e-05 | P53: 1.6223055e+09 | Q53: 174 | S53: 713 | T53: 0.95409326
G54: 1.6408399e+09 | H54: 172 | I54: 0.96300518 | L54: 53 | M54: 53 | N54: 0.0040910962 | P54: 1.6408399e+09 | Q54: 172 | T54: 0.96300518
G55: 1.6593743e+09 | H55: 121 | I55: 0.96927461 | L55: 54 | M55: 54 | N55: 0.0019551031 | P55: 1.6593743e+09 | Q55: 121 | T55: 0.96927461
G56: 1.6779087e+09 | H56: 101 | I56: 0.97450777 | L56: 55 | M56: 55 | N56: 0.0040711686 | P56: 1.6779087e+09 | Q56: 101 | T56: 0.97450777
G57: 1.6964431e+09 | H57: 96 | I57: 0.97948187 | L57: 56 | M57: 56 | N57: 0.00022558617 | P57: 1.6964431e+09 | Q57: 96 | T57: 0.97948187
...
